<?xml version='1.0'?>

<robot name="robot" xmlns:xacro="http://www.ros.org/wiki/xacro">
	<xacro:property name="robot_name" value="robot" />
	<xacro:property name="robot_chassis_mass" value="15"/>
	<xacro:property name="robot_chassis_length" value="0.2"/>
	<xacro:property name="robot_chassis_radius" value="0.25"/>
	<xacro:property name="robot_caster_wheel_radius" value="0.05"/>
	<xacro:property name="robot_caster_wheel_radius_collision" value="0.0499"/>

	<xacro:property name="robot_wheel_mass" value="5"/>
	<xacro:property name="robot_wheel_length" value="0.05"/>
	<xacro:property name="robot_wheel_radius" value="0.1"/>

	<xacro:property name="camera_mass" value="0.1"/>
	<xacro:property name="hokoyu_mass" value="1e-5"/>

	<!-- Make Chassis of Bot -->
	<link name="chassis">
		<pose>0 0 0.1 0 0 0</pose>

		<inertial>
			<mass value="${robot_chassis_mass}"/>
      		<origin xyz="0.0 0 0" rpy=" 0 0 0"/>

      		<inertia 
      			ixx="0.147116667" ixy="0" ixz="0"
      			iyy="0.334951167" iyz="0"
      			izz="0.3978345"
      		/>
		</inertial>

		<collision name="collision">
			<origin xyz="0 0 0.05" rpy=" 0 0 0"/>
			<geometry>
				<box size="0.5 0.5 0.2"/>
			</geometry>
		</collision>

		<visual name="chassis_visual">
			<origin xyz="0 0 0.05" rpy=" 0 0 0"/>
			<geometry>
				<box size="0.5 0.5 0.2"/>
			</geometry>

		</visual>

	</link>


	<!-- Right Wheel Back -->
	<link name="right_wheel_back">
		<inertial>
			<mass value="${robot_wheel_mass}"/>
			<origin xyz="0 0 0" rpy="0 1.5707 1.5707"/>
			<inertia
				ixx="0.1" ixy="0.0" ixz="0.0"
				iyy="0.1" iyz="0.0"
				izz="0.1"
			/>
		</inertial>

		<visual>
			<origin xyz="0 0 0" rpy="0 1.5707 1.5707"/>
			<geometry>
				<cylinder radius="${robot_wheel_radius}" length="${robot_wheel_length}"/>
			</geometry>
		</visual>

		<collision>
			<origin xyz="0 0 0" rpy="0 1.5707 1.5707"/>
			<geometry>
				<cylinder radius="${robot_wheel_radius}" length="${robot_wheel_length}"/>
			</geometry>
		</collision>

	</link>

	<!-- Right Wheel Front-->
	<link name="right_wheel_front">
		<inertial>
			<mass value="${robot_wheel_mass}"/>
			<origin xyz="0 0 0" rpy="0 1.5707 1.5707"/>
			<inertia
				ixx="0.1" ixy="0.0" ixz="0.0"
				iyy="0.1" iyz="0.0"
				izz="0.1"
			/>
		</inertial>

		<visual>
			<origin xyz="0 0 0" rpy="0 1.5707 1.5707"/>
			<geometry>
				<cylinder radius="${robot_wheel_radius}" length="${robot_wheel_length}"/>
			</geometry>
		</visual>

		<collision>
			<origin xyz="0 0 0" rpy="0 1.5707 1.5707"/>
			<geometry>
				<cylinder radius="${robot_wheel_radius}" length="${robot_wheel_length}"/>
			</geometry>
		</collision>

	</link>



	<!-- Left wheel Back-->
	<link name="left_wheel_back">
		<inertial>
			<mass value="${robot_wheel_mass}"/>
			<origin xyz="0 0 0" rpy="0 1.5707 1.5707"/>
			<inertia
				ixx="0.1" ixy="0.0" ixz="0.0"
				iyy="0.1" iyz="0.0"
				izz="0.1"
			/>
		</inertial>

		<visual>
			<origin xyz="0 0 0" rpy="0 1.5707 1.5707"/>
			<geometry>
				<cylinder radius="${robot_wheel_radius}" length="${robot_wheel_length}"/>
			</geometry>
		</visual>

		<collision>
			<origin xyz="0 0 0" rpy="0 1.5707 1.5707"/>
			<geometry>
				<cylinder radius="${robot_wheel_radius}" length="${robot_wheel_length}"/>
			</geometry>
		</collision>

	</link>

	<!-- Left wheel Front-->
	<link name="left_wheel_front">
		<inertial>
			<mass value="${robot_wheel_mass}"/>
			<origin xyz="0 0 0" rpy="0 1.5707 1.5707"/>
			<inertia
				ixx="0.1" ixy="0.0" ixz="0.0"
				iyy="0.1" iyz="0.0"
				izz="0.1"
			/>
		</inertial>

		<visual>
			<origin xyz="0 0 0" rpy="0 1.5707 1.5707"/>
			<geometry>
				<cylinder radius="${robot_wheel_radius}" length="${robot_wheel_length}"/>
			</geometry>
		</visual>

		<collision>
			<origin xyz="0 0 0" rpy="0 1.5707 1.5707"/>
			<geometry>
				<cylinder radius="${robot_wheel_radius}" length="${robot_wheel_length}"/>
			</geometry>
		</collision>

	</link>


	<!-- Hokuyo Lidar -->
	<link name="hokuyo">
		<inertial>
			<mass value="${hokoyu_mass}"/>
			<origin xyz="0 0 0" rpy="0 0 0"/>

			<inertia
		        ixx="1e-6" ixy="0.0" ixz="0.0"
		        iyy="1e-6" iyz="0.0"
		        izz="1e-6"
		      />
		</inertial>

		<visual>
			<origin xyz="0 0 0" rpy="0 0 0"/>
			<geometry>
				<mesh filename="package://assignment2/meshes/hokuyo.dae"/> 
			</geometry>
		</visual>

		<collision>
			<origin xyz="0 0 0" rpy="0 0 0"/>
			<geometry>
				<box size="0.1 0.1 0.1"/>
			</geometry>
		</collision>
	</link>
	
	<link name="arm_base">
		<inertial>
			<mass value="0.1"/>
			<origin xyz="0 0 0" rpy="0 0 0" />
			<inertia ixx="0.0" ixy="0" ixz="0" iyy="0.0" iyz="0" izz="0.0"/>
		</inertial>
		<collision>
			<origin xyz="0 0 0" rpy="0 0 0"/>
			<geometry>
				<box size="0.1 0.1 0.1"/>
			</geometry>
		</collision>
		<visual>
			<origin xyz="0 0 0" rpy="0 0 0"/>
			<geometry>
				<box size="0.1 0.1 0.1"/>
			</geometry>
			<material name="white" />
		</visual>
	</link>

	<link name="arm_L1">
		<inertial>
			<mass value="0.0025"/>
			<origin xyz="0 0 0" rpy="0 0 0" />
			<inertia ixx="0.0" ixy="0" ixz="0" iyy="0.0" iyz="0" izz="0.0"/>
		</inertial>
		<collision>
			<origin xyz="0 0 0" rpy="0 0 0"/>
			<geometry>
				<cylinder radius="0.04" length="0.08"/>
			</geometry>
		</collision>
		<visual>
			<origin xyz="0 0 0" rpy="0 0 0"/>
			<geometry>
				<cylinder radius="0.04" length="0.08"/>
			</geometry>
			<material name="white" />
		</visual>
	</link>
	

	<link name="arm_L2">
		<inertial>
			<mass value="0.0025"/>
			<origin xyz="0 0 0" rpy="0 0 0" />
			<inertia ixx="0.0" ixy="0" ixz="0" iyy="0.0" iyz="0" izz="0.0"/>
		</inertial>
		<collision>
			<origin xyz="0 0 0.04" rpy="0 0 0"/>
			<geometry>
				<cylinder radius="0.04" length="0.08"/>
			</geometry>
		</collision>
		<visual>
			<origin xyz="0 0 0.04" rpy="0 0 0"/>
			<geometry>
				<cylinder radius="0.04" length="0.08"/>
			</geometry>
			<material name="white" />
		</visual>
  	</link>

	<link name="arm_L3">
		<inertial>
			<mass value="0.0025"/>
			<origin xyz="0 0 0" rpy="0 0 0" />
			<inertia ixx="0.0" ixy="0" ixz="0" iyy="0.0" iyz="0" izz="0.0"/>
		</inertial>
		<collision>
			<origin xyz="0 0 0.04" rpy="0 0 0"/>
			<geometry>
				<cylinder radius="0.04" length="0.08"/>
			</geometry>
		</collision>
		<visual>
			<origin xyz="0 0 0.04" rpy="0 0 0"/>
			<geometry>
				<cylinder radius="0.04" length="0.08"/>
			</geometry>
			<material name="white" />
		</visual>
	</link>
	<!-- Camera -->
	<!-- <link name="camera">
		<inertial>
			<mass value="${camera_mass}"/>
			<origin xyz="0 0 0" rpy="0 0 0"/>
			<inertia
		        ixx="1e-6" ixy="0.0" ixz="0.0"
		        iyy="1e-6" iyz="0.0"
		        izz="1e-6"
		      />
		</inertial>

		<visual>
			<origin xyz="0 0 0" rpy="0 0 0"/>
			<geometry>
				<box size="0.05 0.05 0.05"/>
			</geometry>
		</visual>

		<collision>
			<origin xyz="0 0 0" rpy="0 0 0"/>
			<geometry>
				<box size="0.05 0.05 0.05"/>
			</geometry>
		</collision>
	</link> -->

	  <!-- Camera -->
	<link name="camera">
		<collision>
			<origin xyz="0 0 0" rpy="0 0 0"/>
			<geometry>
				<box size="0.05 0.05 0.05"/>
			</geometry>
		</collision>

		<visual>
			<origin xyz="0 0 0" rpy="0 0 0"/>
			<geometry>
				<box size="0.05 0.05 0.05"/>
			</geometry>
			<material name="white"/>
		</visual>

		<inertial>
			<mass value="${camera_mass}" />
			<origin xyz="0 0 0" rpy="0 0 0"/>
			<inertia ixx="0" ixy="0" ixz="0" iyy="0" iyz="0" izz="0" />
		</inertial>
	</link>

	<!-- Project center to the ground -->
	<link name="robot_footprint"></link>



	<!-- Define Joints -->

	<!-- Right Wheel Joint Back-->
	<joint type="continuous" name="right_wheel_hinge_back">
	    <origin xyz="-0.2 -0.30 0" rpy="0 0 0" />
	    <parent link="chassis"/>
	    <child link="right_wheel_back" />
	    <axis xyz="0 1 0" rpy="0 0 0" />
	    <limit effort="10000" velocity="1000" />
	    <dynamics damping="1.0" friction="1.0" />
	</joint>

	<!-- Right Wheel Joint Front-->
	<joint type="continuous" name="right_wheel_hinge_front">
	    <origin xyz="0.2 -0.30 0" rpy="0 0 0" />
	    <parent link="chassis"/>
	    <child link="right_wheel_front" />
	    <axis xyz="0 1 0" rpy="0 0 0" />
	    <limit effort="10000" velocity="1000" />
	    <dynamics damping="1.0" friction="1.0" />
	</joint>


	<!-- Left Wheel Joint Back-->
	<joint type="continuous" name="left_wheel_hinge_back">
	    <origin xyz="-0.2 0.30 0" rpy="0 0 0" />
	    <parent link="chassis"/>
	    <child link="left_wheel_back" />
	    <axis xyz="0 1 0" rpy="0 0 0" />
	    <limit effort="10000" velocity="1000" />
	    <dynamics damping="1.0" friction="1.0" />
	</joint>

	<!-- Left Wheel Joint Front-->
	<joint type="continuous" name="left_wheel_hinge_front">
	    <origin xyz="0.2 0.30 0" rpy="0 0 0" />
	    <parent link="chassis"/>
	    <child link="left_wheel_front" />
	    <axis xyz="0 1 0" rpy="0 0 0" />
	    <limit effort="10000" velocity="1000" />
	    <dynamics damping="1.0" friction="1.0" />
	</joint>


	<joint name="j_from_arm_to_base" type="fixed">
		<origin rpy="0 0 0" xyz="0.05 0 0.085"/>
		<parent link="chassis"/>
		<child link="arm_base"/>
	</joint>
  
  
   
  
	<joint name="arm_J1" type="revolute">
		<axis xyz="0 0 1"/>
		<limit effort="1000.0" lower="-3.14" upper="3.14" velocity="0.2"/>
		<origin rpy="0 0 0" xyz="0 0 0.09"/>
		<parent link="arm_base"/>
		<child link="arm_L1"/>
	</joint>
  
  
	  
  
	<joint name="arm_J2" type="revolute">
		<axis xyz="1 0 0"/>
		<limit effort="1000.0" lower="-1.8" upper="1.8" velocity="0.2"/>
		<origin rpy="0 0 0" xyz="0 0 0.04"/>
		<parent link="arm_L1"/>
		<child link="arm_L2"/>
	</joint>
  
		
  
	<joint name="arm_J3" type="revolute">
		<axis xyz="1 0 0"/>
		<limit effort="1000.0" lower="-1.8" upper="1.8" velocity="0.2"/>
		<origin rpy="0 0 0" xyz="0 0 0.08"/>
		<parent link="arm_L2"/>
		<child link="arm_L3"/>
	</joint>


	<!-- Camera Joint -->
	<!-- <joint name="camera_joint" type="fixed">
		<origin xyz="0.26 0 0" rpy="0 0 0" />
		<parent link="chassis"/>
		<child link="camera" />
		<axis xyz="0 1 0"/>
	</joint> -->
	<joint name="camera_joint" type="fixed">
		<axis xyz="0 1 0" />
		<origin xyz="0 0.0 0.08" rpy="0 0 0"/>
		<parent link="arm_L3"/>
		<child link="camera"/>
	  </joint>

	<!-- Hokoyu Joint -->
	<joint name="hokuyo_joint" type="fixed">
	    <origin xyz="0.2 0 0.2" rpy="0 0 0" />
	    <parent link="chassis"/>
	    <child link="hokuyo" />  
	    <axis xyz="0 1 0"/> 
	</joint>

	<joint name="robot_footprint_joint" type="fixed">
		<origin xyz="0 0 0" rpy="0 0 0" />
		<parent link="robot_footprint"/>
		<child link="chassis" />
	</joint>


	<!-- Color of bot -->
	<gazebo reference="left_wheel_front">
		<material>Gazebo/Green</material>
		<kp>1000000.0</kp> <!-- kp and kd for rubber -->
		<kd>100.0</kd>
		<mu1>1.0</mu1>
		<mu2>1.0</mu2>
		<maxVel>1.0</maxVel>
		<minDepth>0.00</minDepth>
	</gazebo>

	<gazebo reference="left_wheel_back">
		<material>Gazebo/Green</material>
		<kp>1000000.0</kp> <!-- kp and kd for rubber -->
		<kd>100.0</kd>
		<mu1>1.0</mu1>
		<mu2>1.0</mu2>
		<maxVel>1.0</maxVel>
		<minDepth>0.00</minDepth>
	</gazebo>

	<gazebo reference="right_wheel_front">
		<material>Gazebo/Green</material>
		<kp>1000000.0</kp> <!-- kp and kd for rubber -->
		<kd>100.0</kd>
		<mu1>1.0</mu1>
		<mu2>1.0</mu2>
		<maxVel>1.0</maxVel>
		<minDepth>0.00</minDepth>
	</gazebo>
	<gazebo reference="right_wheel_back">
		<material>Gazebo/Green</material>
		<kp>1000000.0</kp> <!-- kp and kd for rubber -->
		<kd>100.0</kd>
		<mu1>1.0</mu1>
		<mu2>1.0</mu2>
		<maxVel>1.0</maxVel>
		<minDepth>0.00</minDepth>
	</gazebo>
	<!--<gazebo reference="right_wheel">
		<material>Gazebo/Green</material>
	</gazebo>-->
	<gazebo reference="arm_base">
		<material>Gazebo/white</material>
	</gazebo>
	<gazebo reference="arm_L1">
		<material>Gazebo/white</material>
	</gazebo>
	<gazebo reference="arm_L2">
		<material>Gazebo/white</material>
	</gazebo>
	<gazebo reference="arm_L3">
		<material>Gazebo/white</material>
	</gazebo>

	
	
	<gazebo reference="arm_J2">
		<provideFeedback>true</provideFeedback>
	</gazebo>
	<gazebo reference="camera">
		<material>Gazebo/Red</material>
	</gazebo>

	<gazebo reference="chassis">
		<material>Gazebo/Blue</material>
	</gazebo>

	<!-- Motor, Camera and Lidar Simulation -->
	<xacro:include filename="$(find assignment2)/urdf/robot.gazebo" />




	<transmission name="arm_J1_trans">
		<type>transmission_interface/SimpleTransmission</type>
		<joint name="arm_J1">
			<hardwareInterface>hardware_interface/EffortJointInterface</hardwareInterface>
		</joint>
		<actuator name="motor1">
			<hardwareInterface>hardware_interface/EffortJointInterface</hardwareInterface>
			<mechanicalInterface>1</mechanicalInterface>
		</actuator>
	</transmission>
	
	<transmission name="arm_J2_trans">
		<type>transmission_interface/SimpleTransmission</type>
		<joint name="arm_J2">
			<hardwareInterface>hardware_interface/EffortJointInterface</hardwareInterface>
		</joint>
		<actuator name="motor2">
			<hardwareInterface>hardware_interface/EffortJointInterface</hardwareInterface>
			<mechanicalInterface>1</mechanicalInterface>
		</actuator>
	</transmission>
	
	<transmission name="arm_J3_trans">
		<type>transmission_interface/SimpleTransmission</type>
		<joint name="arm_J3">
			<hardwareInterface>hardware_interface/EffortJointInterface</hardwareInterface>
		</joint>
		<actuator name="motor3">
			<hardwareInterface>hardware_interface/EffortJointInterface</hardwareInterface>
			<mechanicalInterface>1</mechanicalInterface>
		</actuator>
	</transmission>
	

</robot>




